Workbook

Sheet 5-Year Temp Svcs Projections
A1: RFP 26-325 | K1: ATTACHMENT 1
A2: TEMPORARY STAFFING AND RECRUITMENT SERVICES
A3: TEMPORARY STAFFING SERVICES | C3: OFFEROR:
A4: YEAR 1 ITEM NO. | B4: Departments | C4: Positions | D4: Current FY25 Pay Rate | E4: Expected Mark-Up % | F4: Mark-Up Dollar Amount | G4: Expected Bill Rate | H4: Projected Annual No. of Hours | I4: Annualized Billable Cost | L4: 5-Year Projections with Mark-Ups
A5: 1 | B5: Information Technology | C5: Business Intelligence Analyst 3 | D5: 121.86 | E5: 0 | F5: =D5*E5 -> 0 | G5: =D5+F5 -> 121.86 | H5: 1250 | I5: =G5*H5 -> 152325 | K5: YR1 | L5: =I28 -> 1696242.7
C6: Business Continuity Analyst 2 | D6: 112 | E6: 0 | F6: =D6*E6 -> 0 | G6: =D6+F6 -> 112 | H6: 1250 | I6: =G6*H6 -> 140000 | K6: YR2 | L6: =I55 -> 1696242.7
C7: Technical Writer Level 2 | D7: 73.94 | E7: 0 | F7: =D7*E7 -> 0 | G7: =D7+F7 -> 73.94 | H7: 1250 | I7: =G7*H7 -> 92425 | K7: YR3 | L7: =I82 -> 1527284.7
C8: Business Intelligence Analyst | D8: 60 | E8: 0 | F8: =D8*E8 -> 0 | G8: =D8+F8 -> 60 | H8: 1250 | I8: =G8*H8 -> 75000 | K8: YR4 | L8: =I109 -> 1449455.4
F9: AVERAGE | G9: =AVERAGE(G5:G8) -> 91.95 | H9: =SUM(H5:H8) -> 5000 | I9: =G9*H9 -> 459750 | K9: YR5 | L9: =I136 -> 1375235.1
A10: 2 | B10: Admin, Clerical & Office Support | C10: Retirement & Pension Specialist | D10: 55 | E10: 0 | F10: =D10*E10 -> 0 | G10: =D10+F10 -> 55 | H10: 833 | I10: =G10*H10 -> 45815
C11: Outreach Support Specialist | D11: 35 | E11: 0 | F11: =D11*E11 -> 0 | G11: =D11+F11 -> 35 | H11: 833 | I11: =G11*H11 -> 29155 | L11: =SUM(L5:L10) -> 7744460.5
C12: Equal Employment Opportunity Specialist | D12: 55 | E12: 0 | F12: =D12*E12 -> 0 | G12: =D12+F12 -> 55 | H12: 833 | I12: =G12*H12 -> 45815
C13: Outreach Support Assistant | D13: 25 | E13: 0 | F13: =D13*E13 -> 0 | G13: =D13+F13 -> 25 | H13: 833 | I13: =G13*H13 -> 20825
C14: Talent Acquisition Specialist | D14: 30 | E14: 0 | F14: =D14*E14 -> 0 | G14: =D14+F14 -> 30 | H14: 833 | I14: =G14*H14 -> 24990 | L14: NOTE: Annualized Billable Cost is based on a 12-month period
C15: Temporary Clerk | D15: 18 | E15: 0 | F15: =D15*E15 -> 0 | G15: =D15+F15 -> 18 | H15: 833 | I15: =G15*H15 -> 14994
F16: AVERAGE | G16: =AVERAGE(G10:G15) -> 36.333333 | H16: =SUM(H10:H15) -> 4998 | I16: =G16*H16 -> 181594
A17: 3 | B17: Professional Services | C17: Legal Support (Legal Assistant) | D17: 60 | E17: 0 | F17: =D17*E17 -> 0 | G17: =D17+F17 -> 60 | H17: 2000 | I17: =G17*H17 -> 120000
C18: Compensation Program Manager | D18: 100 | E18: 0 | F18: =D18*E18 -> 0 | G18: =D18+F18 -> 100 | H18: 2000 | I18: =G18*H18 -> 200000
C19: Communications Coordinator Specialist | D19: 210 | E19: 0 | F19: =D19*E19 -> 0 | G19: =D19+F19 -> 210 | H19: 1000 | I19: =G19*H19 -> 210000
F20: AVERAGE | G20: =AVERAGE(G17:G19) -> 123.33333 | H20: =SUM(H17:H19) -> 5000 | I20: =G20*H20 -> 616666.67
A21: 4 | B21: Finance & Accounting | C21: Fiscal Management Resource / Accting Clerk | D21: 32 | E21: 0 | F21: =D21*E21 -> 0 | G21: =D21+F21 -> 32 | H21: 1666 | I21: =G21*H21 -> 53312
C22: Senior Accountant | D22: 65 | E22: 0 | F22: =D22*E22 -> 0 | G22: =D22+F22 -> 65 | H22: 1666 | I22: =G22*H22 -> 108290
C23: Senior Financial Analyst | D23: 55 | E23: 0 | F23: =D23*E23 -> 0 | G23: =D23+F23 -> 55 | H23: 1666 | I23: =G23*H23 -> 91630
F24: AVERAGE | G24: =AVERAGE(G21:G23) -> 50.666667 | H24: =SUM(H21:H23) -> 4998 | I24: =G24*H24 -> 253232
A25: 5 | B25: General Laborers | C25: Maintenance Support Specialist | D25: 37 | E25: 0 | F25: =D25*E25 -> 0 | G25: =D25+F25 -> 37 | H25: 5000 | I25: =G25*H25 -> 185000
F27: AVERAGE | G27: =AVERAGE(G25:G26) -> 37 | H27: =SUM(H25:H26) -> 5000 | I27: =G27*H27 -> 185000
E28: YEAR 1 TOTALS | H28: =H9+H16+H20+H24+H27 -> 24996 | I28: =I9+I16+I20+I24+I27 -> 1696242.7
A31: YEAR 2 ITEM NO. | B31: Departments | C31: Positions | D31: Current FY25 Pay Rate | E31: Expected Mark-Up % | F31: Mark-Up Dollar Amount | G31: Expected Bill Rate | H31: Projected Annual No. of Hours | I31: Annualized Billable Cost
A32: 1 | B32: Information Technology | C32: Business Intelligence Analyst 3 | D32: 121.86 | E32: 0 | F32: =D32*E32 -> 0 | G32: =D32+F32 -> 121.86 | H32: 1250 | I32: =G32*H32 -> 152325
C33: Business Continuity Analyst 2 | D33: 112 | E33: 0 | F33: =D33*E33 -> 0 | G33: =D33+F33 -> 112 | H33: 1250 | I33: =G33*H33 -> 140000
C34: Technical Writer Level 2 | D34: 73.94 | E34: 0 | F34: =D34*E34 -> 0 | G34: =D34+F34 -> 73.94 | H34: 1250 | I34: =G34*H34 -> 92425
C35: Business Intelligence Analyst | D35: 60 | E35: 0 | F35: =D35*E35 -> 0 | G35: =D35+F35 -> 60 | H35: 1250 | I35: =G35*H35 -> 75000
F36: AVERAGE | G36: =AVERAGE(G32:G35) -> 91.95 | H36: =SUM(H32:H35) -> 5000 | I36: =G36*H36 -> 459750
A37: 2 | B37: Admin, Clerical & Office Support | C37: Retirement & Pension Specialist | D37: 55 | E37: 0 | F37: =D37*E37 -> 0 | G37: =D37+F37 -> 55 | H37: 833 | I37: =G37*H37 -> 45815
C38: Outreach Support Specialist | D38: 35 | E38: 0 | F38: =D38*E38 -> 0 | G38: =D38+F38 -> 35 | H38: 833 | I38: =G38*H38 -> 29155
C39: Equal Employment Opportunity Specialist | D39: 55 | E39: 0 | F39: =D39*E39 -> 0 | G39: =D39+F39 -> 55 | H39: 833 | I39: =G39*H39 -> 45815
C40: Outreach Support Assistant | D40: 25 | E40: 0 | F40: =D40*E40 -> 0 | G40: =D40+F40 -> 25 | H40: 833 | I40: =G40*H40 -> 20825
C41: Talent Acquisition Specialist | D41: 30 | E41: 0 | F41: =D41*E41 -> 0 | G41: =D41+F41 -> 30 | H41: 833 | I41: =G41*H41 -> 24990
C42: Temporary Clerk | D42: 18 | E42: 0 | F42: =D42*E42 -> 0 | G42: =D42+F42 -> 18 | H42: 833 | I42: =G42*H42 -> 14994
F43: AVERAGE | G43: =AVERAGE(G37:G42) -> 36.333333 | H43: =SUM(H37:H42) -> 4998 | I43: =G43*H43 -> 181594
...

Sheet 5-Year Direct Hire Projections
B1: RFP 26-325 | N1: ATTACHMENT 1
B2: TEMPORARY STAFFING AND RECRUITMENT SERVICES
A3: DIRECT PLACEMENT SERVICES
A4: Item No. | B4: Estimated Base Salary | C4: YEAR 1 Percentage of Base Salary | D4: Mark-Up Dollar Amount | E4: YEAR 2 Percentage of Base Salary | F4: Mark-Up Dollar Amount | G4: YEAR 3 Percentage of Base Salary | H4: Mark-Up Dollar Amount | I4: YEAR 4 Percentage of Base Salary | J4: Mark-Up Dollar Amount | K4: YEAR 5 Percentage of Base Salary | L4: Mark-Up Dollar Amount | O4: 5-Year Direct Hire Mark-Up Projections
A5: 1* | B5: 100000 | C5: 0 | D5: =B5*C5 -> 0 | E5: 0 | F5: =B5*E5 -> 0 | G5: 0 | H5: =B5*G5 -> 0 | I5: 0 | J5: =B5*I5 -> 0 | K5: 0 | L5: =B5*K5 -> 0 | N5: YR1 | O5: =D5+D6+D7+D8 -> 0
A6: 2 | B6: 150000 | C6: 0 | D6: =B6*C6 -> 0 | E6: 0 | F6: =B6*E6 -> 0 | G6: 0 | H6: =B6*G6 -> 0 | I6: 0 | J6: =B6*I6 -> 0 | K6: 0 | L6: =B6*K6 -> 0 | N6: YR2 | O6: =F5+F6+F7+F8 -> 0
A7: 3 | B7: 200000 | C7: 0 | D7: =B7*C7 -> 0 | E7: 0 | F7: =B7*E7 -> 0 | G7: 0 | H7: =B7*G7 -> 0 | I7: 0 | J7: =B7*I7 -> 0 | K7: 0 | L7: =B7*K7 -> 0 | N7: YR3 | O7: =H5+H6+H7+H8 -> 0
A8: 4** | B8: 250000 | C8: 0 | D8: =B8*C8 -> 0 | E8: 0 | F8: =B8*E8 -> 0 | G8: 0 | H8: =B8*G8 -> 0 | I8: 0 | J8: =B8*I8 -> 0 | K8: 0 | L8: =B8*K8 -> 0 | N8: YR4 | O8: =J5+J6+J7+J8 -> 0
B9: YEARLY TOTALS | C9: YEAR 1 | D9: =SUM(D5:D8) -> 0 | E9: YEAR 2 | F9: =SUM(F5:F8) -> 0 | G9: YEAR 3 | H9: =SUM(H5:H8) -> 0 | I9: YEAR 4 | J9: =SUM(J5:J8) -> 0 | K9: YEAR 5 | L9: =SUM(L5:L8) -> 0 | N9: YR5 | O9: =L5+L6+L7+L8 -> 0
B11: NOTE: | O11: =SUM(O5:O10) -> 0
B12: The Mark-Up Dollar Amount is a one-time payment paid by VIA to the Offeror for the selected direct hire candidate.
B13: For evalaution purposes, assume a quantity of one (1) each per Estimated Base Salary (recruitment item) annually.
A14: * | B14: Up to $100,00 1st year Base salary
A15: ** | B15: ≥ $200,000 1st year Base salary

Sheet 5-Year Category Totals
C3: Projected Temporary Staffing Expenses Per Category
C4: Information Technology | D4: Admin, Clerical & Office Support | E4: Professional Services | F4: Finance & Accounting | G4: General Laborers
B5: Year 1 | C5: ='5-Year Temp Svcs Projections'!I9 -> 459750 | D5: ='5-Year Temp Svcs Projections'!I16 -> 181594 | E5: ='5-Year Temp Svcs Projections'!I20 -> 616666.67 | F5: ='5-Year Temp Svcs Projections'!I24 -> 253232 | G5: ='5-Year Temp Svcs Projections'!I27 -> 185000
B6: Year 2 | C6: ='5-Year Temp Svcs Projections'!I36 -> 459750 | D6: ='5-Year Temp Svcs Projections'!I43 -> 181594 | E6: ='5-Year Temp Svcs Projections'!I47 -> 616666.67 | F6: ='5-Year Temp Svcs Projections'!I51 -> 253232 | G6: ='5-Year Temp Svcs Projections'!I54 -> 185000
B7: Year 3 | C7: ='5-Year Temp Svcs Projections'!I63 -> 413775 | D7: ='5-Year Temp Svcs Projections'!I70 -> 163500 | E7: ='5-Year Temp Svcs Projections'!I74 -> 555246.67 | F7: ='5-Year Temp Svcs Projections'!I78 -> 228152 | G7: ='5-Year Temp Svcs Projections'!I81 -> 166611
A8: Subtotal YR1 - YR3 | C8: =SUM(C5:C7) -> 1333275 | D8: =SUM(D5:D7) -> 526688 | E8: =SUM(E5:E7) -> 1788580 | F8: =SUM(F5:F7) -> 734616 | G8: =SUM(G5:G7) -> 536611
B9: Year 4 | C9: ='5-Year Temp Svcs Projections'!I90 -> 392810.4 | D9: ='5-Year Temp Svcs Projections'!I97 -> 155216 | E9: ='5-Year Temp Svcs Projections'!I101 -> 526880 | F9: ='5-Year Temp Svcs Projections'!I105 -> 216448 | G9: ='5-Year Temp Svcs Projections'!I108 -> 158101
B10: Year 5 | C10: ='5-Year Temp Svcs Projections'!I117 -> 372581.4 | D10: ='5-Year Temp Svcs Projections'!I124 -> 147150 | E10: ='5-Year Temp Svcs Projections'!I128 -> 500116.67 | F10: ='5-Year Temp Svcs Projections'!I132 -> 205352 | G10: ='5-Year Temp Svcs Projections'!I135 -> 150035
A11: Subtotal YR4 - YR 5 | C11: =SUM(C9:C10) -> 765391.8 | D11: =SUM(D9:D10) -> 302366 | E11: =SUM(E9:E10) -> 1026996.7 | F11: =SUM(F9:F10) -> 421800 | G11: =SUM(G9:G10) -> 308136
B12: 5-YR Total | C12: =C8+C11 -> 2098666.8 | D12: =D8+D11 -> 829054 | E12: =E8+E11 -> 2815576.7 | F12: =F8+F11 -> 1156416 | G12: =G8+G11 -> 844747 | H12: =SUM(C12:G12) -> 7744460.5
C16: Projected Direct Hire Mark-Up Dollar Amounts Per Salary Range
C17: up to $100K | D17: $150K | E17: $200K | F17: $250K+ | G17: Total
B18: Year 1 | C18: ='5-Year Direct Hire Projections'!D5 -> 0 | D18: ='5-Year Direct Hire Projections'!D6 -> 0 | E18: ='5-Year Direct Hire Projections'!D7 -> 0 | F18: ='5-Year Direct Hire Projections'!D8 -> 0 | G18: =SUM(C18:F18) -> 0
B19: Year 2 | C19: ='5-Year Direct Hire Projections'!F5 -> 0 | D19: ='5-Year Direct Hire Projections'!F6 -> 0 | E19: ='5-Year Direct Hire Projections'!F7 -> 0 | F19: ='5-Year Direct Hire Projections'!F8 -> 0 | G19: =SUM(C19:F19) -> 0
B20: Year 3 | C20: ='5-Year Direct Hire Projections'!H5 -> 0 | D20: ='5-Year Direct Hire Projections'!H6 -> 0 | E20: ='5-Year Direct Hire Projections'!H7 -> 0 | F20: ='5-Year Direct Hire Projections'!H8 -> 0 | G20: =SUM(C20:F20) -> 0
B21: Year 4 | C21: ='5-Year Direct Hire Projections'!J5 -> 0 | D21: ='5-Year Direct Hire Projections'!J6 -> 0 | E21: ='5-Year Direct Hire Projections'!J7 -> 0 | F21: ='5-Year Direct Hire Projections'!J8 -> 0 | G21: =SUM(C21:F21) -> 0
B22: Year 5 | C22: ='5-Year Direct Hire Projections'!L5 -> 0 | D22: ='5-Year Direct Hire Projections'!L6 -> 0 | E22: ='5-Year Direct Hire Projections'!L7 -> 0 | F22: ='5-Year Direct Hire Projections'!L8 -> 0 | G22: =SUM(C22:F22) -> 0
B23: 5-YR Total | C23: =SUM(C18:C22) -> 0 | D23: =SUM(D18:D22) -> 0 | E23: =SUM(E18:E22) -> 0 | F23: =SUM(F18:F22) -> 0 | G23: =SUM(C23:F23) -> 0

Sheet 5-Year Projections Plus
A2: Year 1 | B2: Departments | C2: Positions | D2: Current FY25 Pay Rate | E2: Expected Mark-Up % | F2: Mark-Up Dollar Amount | G2: Expected Bill Rate | H2: Projected Annual No. of Hours | I2: Annualized Billable Cost | N2: 5-Year Projections
B3: Information Technology | C3: Business Intelligence Analyst 3 | D3: 121.86 | E3: 0 | F3: =D3*E3 -> 0 | G3: =D3+F3 -> 121.86 | H3: 1000 | I3: =G3*H3 -> 121860 | M3: YR1 | N3: =I25 -> 1197626
C4: Business Continuity Analyst 2 | D4: 112 | E4: 0 | F4: =D4*E4 -> 0 | G4: =D4+F4 -> 112 | H4: 1000 | I4: =G4*H4 -> 112000 | M4: YR2 | N4: =I51 -> 1197626
C5: Communications Coordinator Specialist | D5: 210 | E5: 0 | F5: =D5*E5 -> 0 | G5: =D5+F5 -> 210 | H5: 1000 | I5: =G5*H5 -> 210000 | M5: YR3 | N5: =I77 -> 1078283
C6: Technical Writer Level 2 | D6: 73.94 | E6: 0 | F6: =D6*E6 -> 0 | G6: =D6+F6 -> 73.94 | H6: 1000 | I6: =G6*H6 -> 73940 | M6: YR4 | N6: =I103 -> 1023206.2
C7: Business Intelligence Analyst | D7: 60 | E7: 0 | F7: =D7*E7 -> 0 | G7: =D7+F7 -> 60 | H7: 1000 | I7: =G7*H7 -> 60000 | M7: YR5 | N7: =I129 -> 971132.8
J8: =SUM(I3:I7) -> 577800
B9: Admin, Clerical & Office Support | C9: Retirement & Pension Specialist | D9: 55 | E9: 0 | F9: =D9*E9 -> 0 | G9: =D9+F9 -> 55 | H9: 833 | I9: =G9*H9 -> 45815 | K9: 5-Year Total w/Mark-Up | N9: =SUM(N3:N8) -> 5467874
C10: Outreach Support Specialist | D10: 35 | E10: 0 | F10: =D10*E10 -> 0 | G10: =D10+F10 -> 35 | H10: 833 | I10: =G10*H10 -> 29155
C11: EEO Specialist | D11: 55 | E11: 0 | F11: =D11*E11 -> 0 | G11: =D11+F11 -> 55 | H11: 833 | I11: =G11*H11 -> 45815
C12: Outreach Support Assistant | D12: 25 | E12: 0 | F12: =D12*E12 -> 0 | G12: =D12+F12 -> 25 | H12: 833 | I12: =G12*H12 -> 20825
C13: Talent Acquisition Specialist | D13: 30 | E13: 0 | F13: =D13*E13 -> 0 | G13: =D13+F13 -> 30 | H13: 833 | I13: =G13*H13 -> 24990
C14: Temporary Clerk | D14: 18 | E14: 0 | F14: =D14*E14 -> 0 | G14: =D14+F14 -> 18 | H14: 833 | I14: =G14*H14 -> 14994
J15: =SUM(I9:I14) -> 181594
B16: Legal Support | D16: 0 | E16: 0 | F16: =D16*E16 -> 0 | G16: =D16+F16 -> 0 | H16: 5000 | I16: =G16*$Q$4 -> 0 | K16: Using Current Totals: Before Mark-Up % Added | O16: Current 5-Year Grand Totals With Mark-Ups
J18: =SUM(I16) -> 0 | K18: 5-Year Total w/o Mark-Up | N18: 5467874
B19: Finance & Accounting | C19: Fiscal Management Resource / Accting Clerk | D19: 32 | E19: 0 | F19: =D19*E19 -> 0 | G19: =D19+F19 -> 32 | H19: 1666 | I19: =G19*H19 -> 53312 | K19: 20% Mark-Up | N19: =N18*0.2 -> 1093574.8 | O19: =$N$18+N19 -> 6561448.8
C20: Senior Accountant | D20: 65 | E20: 0 | F20: =D20*E20 -> 0 | G20: =D20+F20 -> 65 | H20: 1666 | I20: =G20*H20 -> 108290 | K20: 30% Mark-Up | N20: =N18*0.3 -> 1640362.2 | O20: =$N$18+N20 -> 7108236.2
C21: Senior Financial Analyst | D21: 55 | E21: 0 | F21: =D21*E21 -> 0 | G21: =D21+F21 -> 55 | H21: 1666 | I21: =G21*H21 -> 91630 | K21: 40% Mark-Up | N21: =N18*0.4 -> 2187149.6 | O21: =$N$18+N21 -> 7655023.6
J22: =SUM(I19:I21) -> 253232
B23: General Laborers | C23: Maintenance Support Specialist | D23: 37 | E23: 0 | F23: =D23*E23 -> 0 | G23: =D23+F23 -> 37 | H23: 5000 | I23: =G23*H23 -> 185000
H25: =SUM(H3:H24) -> 24996 | I25: =SUM(I3:I23) -> 1197626 | J25: =SUM(I23) -> 185000
A28: Year 2 | B28: Departments | C28: Positions | D28: Current FY25 Pay Rate | E28: Expected Mark-Up % | F28: Mark-Up Dollar Amount | G28: Expected Bill Rate | H28: Projected Annual No. of Hours | I28: Annualized Billable Cost
B29: Information Technology | C29: Business Intelligence Analyst 3 | D29: 121.86 | E29: 0 | F29: =D29*E29 -> 0 | G29: =D29+F29 -> 121.86 | H29: 1000 | I29: =G29*H29 -> 121860
C30: Business Continuity Analyst 2 | D30: 112 | E30: 0 | F30: =D30*E30 -> 0 | G30: =D30+F30 -> 112 | H30: 1000 | I30: =G30*H30 -> 112000
C31: Communications Coordinator Specialist | D31: 210 | E31: 0 | F31: =D31*E31 -> 0 | G31: =D31+F31 -> 210 | H31: 1000 | I31: =G31*H31 -> 210000
C32: Technical Writer Level 2 | D32: 73.94 | E32: 0 | F32: =D32*E32 -> 0 | G32: =D32+F32 -> 73.94 | H32: 1000 | I32: =G32*H32 -> 73940
C33: Business Intelligence Analyst | D33: 60 | E33: 0 | F33: =D33*E33 -> 0 | G33: =D33+F33 -> 60 | H33: 1000 | I33: =G33*H33 -> 60000
J34: =SUM(I29:I33) -> 577800 | N34: Information Technology | P34: =J8+J34+J60+J86+J112 -> 2637657
B35: Admin, Clerical & Office Support | C35: Retirement & Pension Specialist | D35: 55 | E35: 0 | F35: =D35*E35 -> 0 | G35: =D35+F35 -> 55 | H35: 833 | I35: =G35*H35 -> 45815 | N35: Admin, Clerical & Office Support | P35: =J15+J41+J67+J93+J119 -> 829054
C36: Outreach Support Specialist | D36: 35 | E36: 0 | F36: =D36*E36 -> 0 | G36: =D36+F36 -> 35 | H36: 833 | I36: =G36*H36 -> 29155 | N36: Legal Support | P36: =J18+J44+J70+J96+J122 -> 0
C37: EEO Specialist | D37: 55 | E37: 0 | F37: =D37*E37 -> 0 | G37: =D37+F37 -> 55 | H37: 833 | I37: =G37*H37 -> 45815 | N37: Finance & Accounting | P37: =J22+J48+J74+J100+J126 -> 1156416
C38: Outreach Support Assistant | D38: 25 | E38: 0 | F38: =D38*E38 -> 0 | G38: =D38+F38 -> 25 | H38: 833 | I38: =G38*H38 -> 20825 | N38: General Laborers | P38: =J25+J51+J77+J103+J129 -> 844747
C39: Talent Acquisition Specialist | D39: 30 | E39: 0 | F39: =D39*E39 -> 0 | G39: =D39+F39 -> 30 | H39: 833 | I39: =G39*H39 -> 24990 | P39: =SUM(P34:P38) -> 5467874
C40: Temporary Clerk | D40: 18 | E40: 0 | F40: =D40*E40 -> 0 | G40: =D40+F40 -> 18 | H40: 833 | I40: =G40*H40 -> 14994
J41: =SUM(I35:I40) -> 181594
B42: Legal Support | D42: 0 | E42: 0 | F42: =D42*E42 -> 0 | G42: =D42+F42 -> 0 | H42: 5000 | I42: =G42*$Q$4 -> 0
J44: =SUM(I42) -> 0
B45: Finance & Accounting | C45: Fiscal Management Resource / Accting Clerk | D45: 32 | E45: 0 | F45: =D45*E45 -> 0 | G45: =D45+F45 -> 32 | H45: 1666 | I45: =G45*H45 -> 53312
C46: Senior Accountant | D46: 65 | E46: 0 | F46: =D46*E46 -> 0 | G46: =D46+F46 -> 65 | H46: 1666 | I46: =G46*H46 -> 108290
...
